...F.
======================================================================
FAIL: test_func_subtracao_dois (__main__.MyTestCase)
----------------------------------------------------------------------
Traceback (most recent call last):
  File "test.py", line 23, in test_func_subtracao_dois
    self.assertEqual(test_subtracao, 5)
AssertionError: 1 != 5

----------------------------------------------------------------------
Ran 5 tests in 0.001s

FAILED (failures=1)
